Workbook

Sheet Control
A1: FORENSIC VALUATION MODEL — CONTROL & SUMMARY
A3: Legend: | B3: Blue = input (overwrite) | D3: Green = cross-sheet link
A4: Black = formula | B4: Yellow = refresh each analysis
A6: ENGAGEMENT
A7: Ticker | B7: XMPL
A8: Company | B8: Example Co. (PLACEHOLDER — overwrite all blue cells)
A9: Sector / Logic Track | B9: Standard
A10: Analysis date | B10: 2026-05-29
A11: Currency / units | B11: USD, $mm unless /sh
A13: SUMMARY DASHBOARD
A14: Metric | B14: Value
A15: Current price P0 ($/sh) | B15: =Phase1_Anchor!B5 -> 100
A16: Fair Value — Track A ($/sh) | B16: =FCFF_DCF!B33 -> 63.629714
A17: Fair Value — Track B ($/sh) | B17: =FCFF_DCF!C33 -> 103.88947
A18: Fair Value — average ($/sh) | B18: =AVERAGE(B16:B17) -> 83.759594
A19: Margin of Safety | B19: =(B18-B15)/B15 -> -0.16240406
A20: Institutional rating | B20: Hold
A22: NOTE: dashboard links default to the Standard FCFF track (FCFF_DCF).
A23: If track = Banks/Insurance, repoint B16:B17 to Val_Fin_RI!B25/C25.
A24: If track = REIT, repoint B16:B17 to Val_REIT_NAV!B13/C13.
A26: VALUATION METHOD BY TRACK
A27: Track | B27: Method / tab
A28: Standard | B28: FCFF DCF → equity bridge (FCFF_DCF)
A29: Banks / Insurance | B29: Residual income / DDM at r_e (Val_Fin_RI)
A30: REIT | B30: NAV + AFFO-yield (Val_REIT_NAV)
A32: FORWARD DRIVERS (estimated forward)
A33: Stage-1 growth g0 | B33: =FCFF_DCF!B9 -> 0.05 | C33: =FCFF_DCF!C9 -> 0.1
A34: Terminal growth g | B34: =FCFF_DCF!B6 -> 0 | C34: =FCFF_DCF!C6 -> 0.02
A35: Base FCFF yr0 ($mm) | B35: =FCFF_DCF!B5 -> 2500 | C35: =FCFF_DCF!C5 -> 2700
A36: Normalized OCF ($mm) | B36: =FCFF_DCF!B42 -> 3413.1 | C36: =FCFF_DCF!C42 -> 3613.1
A37: Normalized capex ($mm) | B37: =FCFF_DCF!B43 -> 1000 | C37: =FCFF_DCF!C43 -> 1000
A38: Through-cycle ROE (fin) | B38: =Val_Fin_RI!B12 -> 0.1 | C38: =Val_Fin_RI!B16 -> 0.12
A39: Cap rate (REIT) | B39: =Val_REIT_NAV!B6 -> 0.06 | C39: =Val_REIT_NAV!C6 -> 0.0675
A41: KEY ASSUMPTIONS
A42: Risk-free r_f (refresh) | B42: =WACC_Build!B4 -> 0.0445
A43: Equity risk premium ERP (refresh) | B43: =WACC_Build!B5 -> 0.0423
A44: Beta (relevered) | B44: =WACC_Build!B6 -> 1.1
A45: Pre-tax r_d / tax t | B45: =WACC_Build!B10 -> 0.055 | C45: =WACC_Build!B11 -> 0.21
A46: r_e / WACC | B46: =WACC_Build!B7 -> 0.09103 | C46: =WACC_Build!B22 -> 0.089267778
A47: Terminal-g cap (GDP & <= r_f) | B47: 0.035
...

Sheet Phase1_Anchor
A1: PHASE 1 — DATA ANCHORING
A3: MARKET DATA
A4: Metric | B4: Value | C4: Source / note
A5: Current price P0 ($/sh) | B5: 100 | C5: [REFRESH] live quote, analysis date
A6: Shares — basic (mm) | B6: 500 | C6: 10-Q cover
A7: Shares — diluted (mm) | B7: 520 | C7: 10-Q, diluted WASO
A8: Market cap ($mm) | B8: =B5*B7 -> 52000 | C8: price x diluted shares
A9: 52-week high ($) | B9: 130
A10: 52-week low ($) | B10: 80
A12: EQUITY BRIDGE ITEMS ($mm)
A13: Metric | B13: Value | C13: Source / note
A14: Total debt | B14: 2000 | C14: B/S, latest 10-Q
A15: Cash & equivalents | B15: 800 | C15: B/S
A16: Net debt | B16: =B14-B15 -> 1200 | C16: total debt less cash
A17: Minority interest | B17: 50 | C17: B/S
A18: Preferred equity | B18: 0 | C18: B/S
A19: Non-operating investments | B19: 100 | C19: equity-method / securities
A21: PRIMARY SOURCE ANCHOR
A22: Latest 10-K — filing date | B22: FY2025 10-K — [date]
A23: Latest 10-Q — filing date | B23: Q1 2026 10-Q — [date]
A24: Latest earnings transcript | B24: Q1 2026 call — [date]
A26: INVESTMENT THESIS
A27: [Bull thesis + operating narrative, 3–4 sentences. Cite filings.]

Sheet Phase2_UnitEcon
A1: PHASE 2 — UNIT ECONOMICS
A3: REVENUE ARCHITECTURE ($mm)
A4: Segment | B4: Revenue | C4: % of total
A5: Segment 1 | B5: 6000 | C5: =IFERROR(B5/$B$8,0) -> 0.6
A6: Segment 2 | B6: 3000 | C6: =IFERROR(B6/$B$8,0) -> 0.3
A7: Segment 3 | B7: 1000 | C7: =IFERROR(B7/$B$8,0) -> 0.1
A8: Total revenue | B8: =SUM(B5:B7) -> 10000 | C8: =IFERROR(SUM(C5:C7),0) -> 1
A10: GROWTH DECOMPOSITION
A11: Total revenue growth (YoY) | B11: 0.12 | C11: organic + inorganic check → | D11: =B12+B13 -> 0.12
A12: Organic | B12: 0.08
A13: Inorganic (M&A) | B13: 0.04
A14: Price | B14: 0.05
A15: Volume | B15: 0.07
A17: MARGINAL UNIT (fill the block for the SELECTED track)
A18: Standard — Retail
A19: Average inventory ($mm) | B19: 1200
A20: COGS ($mm) | B20: 5000
A21: Days Sales of Inventory (DSI) | B21: =IFERROR(B19/B20*365,0) -> 87.6
A22: Standard — SaaS
A23: LTV ($) | B23: 9000
A24: CAC ($) | B24: 3000
A25: LTV / CAC | B25: =IFERROR(B23/B24,0) -> 3
A26: Banks — NIM
A27: Net interest income ($mm) | B27: 1800
A28: Average earning assets ($mm) | B28: 60000
A29: Net interest margin (NIM) | B29: =IFERROR(B27/B28,0) -> 0.03
A30: Insurance — Combined ratio
A31: Incurred losses + LAE ($mm) | B31: 6500
A32: Underwriting expenses ($mm) | B32: 2200
A33: Net earned premiums ($mm) | B33: 9000
A34: Combined ratio | B34: =IFERROR((B31+B32)/B33,0) -> 0.96666667
A35: REIT — NOI / AFFO
A36: Same-store NOI ($mm) | B36: 1500
A37: Same-store NOI growth | B37: 0.03
A38: FFO / share ($) | B38: 4.5
A39: AFFO / share ($) | B39: 4
A41: TERMINAL RISK (10-K Item 1A)
A42: [Single biggest terminal risk. This anchors the Phase 5 rating. Cite Item 1A.]
A45: CONCENTRATION (>=10% flag)
A46: Vector | B46: % of revenue | C46: Flag
...

Sheet Phase3_Forensic
A1: PHASE 3 — FORENSIC CLEANSE & QUALITY
A3: FLUFF FILTER
A4: Comparison basis (EBIT/EBITDA/NI) | B4: EBIT
A5: GAAP ($mm) | B5: 1800
A6: Adjusted ($mm) | B6: 2200
A7: Adjustment burden | B7: =IFERROR(ABS(B6-B5)/ABS(B5),0) -> 0.22222222
A8: Flag (> 20%) | B8: =IF(B7>0.2,"FLAG >20%","ok") -> FLAG >20%
A10: Top add-backs | B10: $mm | C10: Recurring?
A11: 1. Stock-based comp | B11: 250 | C11: Yes — recurring
A12: 2. Restructuring | B12: 100 | C12: Maybe
A13: 3. Impairment | B13: 50 | C13: One-off
A15: R&D CAPITALIZATION (Standard track)
A16: Amortization life n (yrs) | B16: 5
A17: R&D — current year ($mm) | B17: 900
A18: R&D t-1 ($mm) | B18: 800
A19: R&D t-2 ($mm) | B19: 700
A20: R&D t-3 ($mm) | B20: 650
A21: R&D t-4 ($mm) | B21: 600
A22: Amortization this year | B22: =IFERROR(SUM(B18:B21)/B16,0) -> 550
A23: EBIT as-reported ($mm) | B23: =B5 -> 1800
A24: EBIT economic ($mm) | B24: =B23+B17-B22 -> 2150 | C24: EBIT + R&D less amortization
A26: QUALITY SCORECARD
A27: Net income ($mm) | B27: 1400
A28: Cash flow from operations ($mm) | B28: 1900
A29: Cash flow from investing ($mm) | B29: -600
A30: Total assets — begin ($mm) | B30: 22000
A31: Total assets — end ($mm) | B31: 24000
A32: Average total assets | B32: =(B30+B31)/2 -> 23000
A33: Sloan ratio (NI−CFO−CFI)/avg TA | B33: =IFERROR((B27-B28-B29)/B32,0) -> 0.0043478261
A34: Sloan flag (>10%) | B34: =IF(ABS(B33)>0.1,"FLAG","ok") -> ok
A36: Contextual metric (track-specific)
A37: Piotroski F-Score (0–9) [Std/REIT] | B37: 6
A38: Altman Z-Score [Std-Mfg] | B38: 3.2
A39: CET1 ratio [Financials] | B39: 0.115

Sheet WACC_Build
A1: DISCOUNT-RATE BUILD
A3: COST OF EQUITY (CAPM)
A4: Risk-free rate r_f | B4: 0.0445 | C4: [REFRESH] 10Y UST — House Assumptions
A5: Equity risk premium ERP | B5: 0.0423 | C5: [REFRESH] Damodaran implied
A6: Beta β | B6: 1.1 | C6: bottom-up, relevered
A7: Cost of equity r_e | B7: =B4+B6*B5 -> 0.09103 | C7: r_f + beta x ERP
A9: COST OF DEBT
A10: Pre-tax cost of debt r_d | B10: 0.055
A11: Marginal tax rate τ | B11: 0.21
A12: After-tax cost of debt | B12: =B10*(1-B11) -> 0.04345
A14: CAPITAL WEIGHTS
A15: Equity E (market cap) | B15: =Phase1_Anchor!B8 -> 52000
A16: Debt D (total debt) | B16: =Phase1_Anchor!B14 -> 2000
A17: Total capital V | B17: =B15+B16 -> 54000
A18: E / V | B18: =IFERROR(B15/B17,0) -> 0.96296296
A19: D / V | B19: =IFERROR(B16/B17,0) -> 0.037037037
A21: WACC
A22: WACC | B22: =B18*B7+B19*B12 -> 0.089267778 | C22: financials: discount at r_e (B7), not WACC
A24: BOTTOM-UP RELEVERED BETA (set B6 to row 27 if adopting)
A25: Unlevered beta bU | B25: 0.9
A26: Market D/E | B26: =Phase1_Anchor!B14/Phase1_Anchor!B8 -> 0.038461538
A27: Relevered beta bL | B27: =B25*(1+(1-B11)*B26) -> 0.92734615 | C27: bL = bU*(1+(1-t)*D/E)

Sheet FCFF_DCF
A1: PHASE 4A — FCFF DCF (2-stage, 10-yr fade — growth-company structure)
A3: ASSUMPTIONS
B4: Track A (Skeptic) | C4: Track B (Institutional)
A5: Base FCFF yr0 ($mm) | B5: 2500 | C5: 2700
A6: Terminal growth g (yr 10+) | B6: 0 | C6: 0.02
A7: WACC | B7: =WACC_Build!B22 -> 0.089267778 | C7: =B7 -> 0.089267778
A8: WACC > g check | B8: =IF(B7>B6,"OK","ERR") -> OK | C8: =IF(C7>C6,"OK","ERR") -> OK
A9: Stage-1 growth g0 (yr 1, fades linearly to g by yr 10) | B9: 0.05 | C9: 0.1
A10: PROJECTION ($mm)
A11: Period | B11: 1 | C11: 2 | D11: 3 | E11: 4 | F11: 5 | G11: 6 | H11: 7 | I11: 8 | J11: 9 | K11: 10
A12: Track A FCFF | B12: =$B$5*(1+($B$9+($B$6-$B$9)*(B11-1)/9)) -> 2625 | C12: =B12*(1+($B$9+($B$6-$B$9)*(C11-1)/9)) -> 2741.6667 | D12: =C12*(1+($B$9+($B$6-$B$9)*(D11-1)/9)) -> 2848.287 | E12: =D12*(1+($B$9+($B$6-$B$9)*(E11-1)/9)) -> 2943.2299 | F12: =E12*(1+($B$9+($B$6-$B$9)*(F11-1)/9)) -> 3024.9863 | G12: =F12*(1+($B$9+($B$6-$B$9)*(G11-1)/9)) -> 3092.2082 | H12: =G12*(1+($B$9+($B$6-$B$9)*(H11-1)/9)) -> 3143.745 | I12: =H12*(1+($B$9+($B$6-$B$9)*(I11-1)/9)) -> 3178.6755 | J12: =I12*(1+($B$9+($B$6-$B$9)*(J11-1)/9)) -> 3196.3349 | K12: =J12*(1+($B$9+($B$6-$B$9)*(K11-1)/9)) -> 3196.3349
A13: Discount factor | B13: =1/(1+$B$7)^B11 -> 0.9180479 | C13: =1/(1+$B$7)^C11 -> 0.84281195 | D13: =1/(1+$B$7)^D11 -> 0.77374175 | E13: =1/(1+$B$7)^E11 -> 0.71033199 | F13: =1/(1+$B$7)^F11 -> 0.65211879 | G13: =1/(1+$B$7)^G11 -> 0.59867629 | H13: =1/(1+$B$7)^H11 -> 0.54961351 | I13: =1/(1+$B$7)^I11 -> 0.50457153 | ... K13: =1/(1+$B$7)^K11 -> 0.42525892
A14: Track A PV | B14: =B12*B13 -> 2409.8757 | C14: =C12*C13 -> 2310.7094 | D14: =D12*D13 -> 2203.8386 | E14: =E12*E13 -> 2090.6704 | F14: =F12*F13 -> 1972.6504 | G14: =G12*G13 -> 1851.2318 | H14: =H12*H13 -> 1727.8448 | I14: =I12*I13 -> 1603.8692 | ... K14: =K12*K13 -> 1359.2699
A15: Track B FCFF | B15: =$C$5*(1+($C$9+($C$6-$C$9)*(B11-1)/9)) -> 2970 | C15: =B15*(1+($C$9+($C$6-$C$9)*(C11-1)/9)) -> 3240.6 | D15: =C15*(1+($C$9+($C$6-$C$9)*(D11-1)/9)) -> 3507.0493 | E15: =D15*(1+($C$9+($C$6-$C$9)*(E11-1)/9)) -> 3764.233 | F15: =E15*(1+($C$9+($C$6-$C$9)*(F11-1)/9)) -> 4006.8169 | G15: =F15*(1+($C$9+($C$6-$C$9)*(G11-1)/9)) -> 4229.4178 | H15: =G15*(1+($C$9+($C$6-$C$9)*(H11-1)/9)) -> 4426.7906 | I15: =H15*(1+($C$9+($C$6-$C$9)*(I11-1)/9)) -> 4594.0249 | J15: =I15*(1+($C$9+($C$6-$C$9)*(J11-1)/9)) -> 4726.7412 | K15: =J15*(1+($C$9+($C$6-$C$9)*(K11-1)/9)) -> 4821.276
A16: Discount factor | B16: =1/(1+$C$7)^B11 -> 0.9180479 | C16: =1/(1+$C$7)^C11 -> 0.84281195 | D16: =1/(1+$C$7)^D11 -> 0.77374175 | E16: =1/(1+$C$7)^E11 -> 0.71033199 | F16: =1/(1+$C$7)^F11 -> 0.65211879 | G16: =1/(1+$C$7)^G11 -> 0.59867629 | H16: =1/(1+$C$7)^H11 -> 0.54961351 | I16: =1/(1+$C$7)^I11 -> 0.50457153 | ... K16: =1/(1+$C$7)^K11 -> 0.42525892
A17: Track B PV | B17: =B15*B16 -> 2726.6023 | C17: =C15*C16 -> 2731.2164 | D17: =D15*D16 -> 2713.5505 | E17: =E15*E16 -> 2673.8551 | F17: =F15*F16 -> 2612.9206 | G17: =G15*G16 -> 2532.0522 | H17: =H15*H16 -> 2433.0239 | I17: =I15*I16 -> 2318.0142 | ... K17: =K15*K16 -> 2050.2906
A19: TERMINAL VALUE & ENTERPRISE VALUE ($mm)
B20: Track A | C20: Track B
A21: Sum PV of FCFF | B21: =SUM(B14:K14) -> 19010.569 | C21: =SUM(B17:K17) -> 24981.051
A22: Terminal value (yr10) | B22: =IFERROR(K12*(1+$B$6)/($B$7-$B$6),0) -> 35806.143 | C22: =IFERROR(K15*(1+$C$6)/($C$7-$C$6),0) -> 70995.515
A23: PV of terminal value | B23: =B22*K13 -> 15226.882 | C23: =C22*K16 -> 30191.476
A24: Enterprise value | B24: =B21+B23 -> 34237.451 | C24: =C21+C23 -> 55172.527
A26: EQUITY BRIDGE ($mm)
A27: (–) Net debt | B27: =Phase1_Anchor!B16 -> 1200 | C27: =B27 -> 1200
A28: (–) Minority interest | B28: =Phase1_Anchor!B17 -> 50 | C28: =B28 -> 50
A29: (–) Preferred | B29: =Phase1_Anchor!B18 -> 0 | C29: =B29 -> 0
A30: (+) Non-op investments | B30: =Phase1_Anchor!B19 -> 100 | C30: =B30 -> 100
A31: Equity value | B31: =B24-B27-B28-B29+B30 -> 33087.451 | C31: =C24-C27-C28-C29+C30 -> 54022.527
A32: Diluted shares (mm) | B32: =Phase1_Anchor!B7 -> 520 | C32: =B32 -> 520
A33: FAIR VALUE / SHARE ($) | B33: =IFERROR(B31/B32,0) -> 63.629714 | C33: =IFERROR(C31/C32,0) -> 103.88947
A35: DIAGNOSTICS (growth-company)
A36: Terminal value % of EV | B36: =IFERROR(B23/B24,0) -> 0.44474344 | C36: =IFERROR(C23/C24,0) -> 0.54721938
A37: Implied exit FCFF multiple (x) | B37: =IFERROR((1+$B$6)/($B$7-$B$6),0) -> 11.20225 | C37: =IFERROR((1+$C$6)/($C$7-$C$6),0) -> 14.725462
A38: Year-10 FCFF ($mm) | B38: =K12 -> 3196.3349 | C38: =K15 -> 4821.276
A40: NORMALIZED FCFF FEEDER (set Base FCFF B5/C5 to row 45 if adopting)
B41: Track A | C41: Track B
A42: Normalized OCF ($mm) | B42: 3413.1 | C42: 3613.1
A43: (-) Normalized capex ($mm) | B43: 1000 | C43: 1000
A44: (+) After-tax interest ($mm) | B44: =Phase1_Anchor!B14*WACC_Build!B10*(1-WACC_Build!B11) -> 86.9 | C44: =B44 -> 86.9
A45: Normalized FCFF (= OCF - capex + a/t int) | B45: =B42-B43+B44 -> 2500 | C45: =C42-C43+C44 -> 2700

Sheet Val_Fin_RI
A1: PHASE 4B — RESIDUAL INCOME (Banks / Insurance)
A2: Value equity directly; discount at cost of equity r_e (NOT WACC). Per-share inputs → per-share output.
A4: ASSUMPTIONS
A5: Cost of equity r_e | B5: =WACC_Build!B7 -> 0.09103
A6: Terminal growth g | B6: 0.02
A7: Payout ratio | B7: 0.3
A8: Book value / share — yr0 ($) | B8: 40
A10: RESIDUAL INCOME SCHEDULE ($/share)
A11: Period | B11: 1 | C11: 2 | D11: 3 | E11: 4 | F11: 5
A12: Track A ROE | B12: 0.1 | C12: 0.1 | D12: 0.1 | E12: 0.1 | F12: 0.1
A13: Track A BV begin | B13: =$B$8 -> 40 | C13: =B13*(1+B12*(1-$B$7)) -> 42.8 | D13: =C13*(1+C12*(1-$B$7)) -> 45.796 | E13: =D13*(1+D12*(1-$B$7)) -> 49.00172 | F13: =E13*(1+E12*(1-$B$7)) -> 52.43184
A14: Track A RI | B14: =(B12-$B$5)*B13 -> 0.3588 | C14: =(C12-$B$5)*C13 -> 0.383916 | D14: =(D12-$B$5)*D13 -> 0.41079012 | E14: =(E12-$B$5)*E13 -> 0.43954543 | F14: =(F12-$B$5)*F13 -> 0.47031361
A15: Track A PV | B15: =B14/(1+$B$5)^B11 -> 0.32886355 | C15: =C14/(1+$B$5)^C11 -> 0.32252459 | D15: =D14/(1+$B$5)^D11 -> 0.31630781 | E15: =E14/(1+$B$5)^E11 -> 0.31021086 | F15: =F14/(1+$B$5)^F11 -> 0.30423143
A16: Track B ROE | B16: 0.12 | C16: 0.12 | D16: 0.12 | E16: 0.12 | F16: 0.12
A17: Track B BV begin | B17: =$B$8 -> 40 | C17: =B17*(1+B16*(1-$B$7)) -> 43.36 | D17: =C17*(1+C16*(1-$B$7)) -> 47.00224 | E17: =D17*(1+D16*(1-$B$7)) -> 50.950428 | F17: =E17*(1+E16*(1-$B$7)) -> 55.230264
A18: Track B RI | B18: =(B16-$B$5)*B17 -> 1.1588 | C18: =(C16-$B$5)*C17 -> 1.2561392 | D18: =(D16-$B$5)*D17 -> 1.3616549 | E18: =(E16-$B$5)*E17 -> 1.4760339 | F18: =(F16-$B$5)*F17 -> 1.6000208
A19: Track B PV | B19: =B18/(1+$B$5)^B11 -> 1.0621156 | C19: =C18/(1+$B$5)^C11 -> 1.0552719 | D19: =D18/(1+$B$5)^D11 -> 1.0484723 | E19: =E18/(1+$B$5)^E11 -> 1.0417165 | F19: =F18/(1+$B$5)^F11 -> 1.0350043
A21: VALUE ($/share)
B22: Track A | C22: Track B
A23: PV of terminal RI | B23: =IFERROR(F14*(1+$B$6)/($B$5-$B$6)/(1+$B$5)^5,0) -> 4.3688028 | C23: =IFERROR(F18*(1+$B$6)/($B$5-$B$6)/(1+$B$5)^5,0) -> 14.862796
A24: Sum PV of RI | B24: =SUM(B15:F15) -> 1.5821382 | C24: =SUM(B19:F19) -> 5.2425807
A25: FAIR VALUE / SHARE ($) | B25: =$B$8+B24+B23 -> 45.950941 | C25: =$B$8+C24+C23 -> 60.105376
A27: DDM CROSS-CHECK ($/share)
A28: Next-year dividend D1 ($) | B28: 2
A29: Value = D1/(r_e − g) | B29: =IFERROR(B28/($B$5-$B$6),0) -> 28.157117

Sheet Val_REIT_NAV
A1: PHASE 4C — NAV + AFFO YIELD (REIT)
A3: NET ASSET VALUE
B4: Track A | C4: Track B
A5: Forward NOI ($mm) | B5: 1500 | C5: =B5 -> 1500
A6: Cap rate | B6: 0.06 | C6: 0.0675
A7: Implied property value | B7: =IFERROR(B5/B6,0) -> 25000 | C7: =IFERROR(C5/C6,0) -> 22222.222
A8: (+) Other assets ($mm) | B8: 200 | C8: =B8 -> 200
A9: (–) Total debt ($mm) | B9: 5000 | C9: =B9 -> 5000
A10: (–) Other liabilities ($mm) | B10: 300 | C10: =B10 -> 300
A11: Net asset value ($mm) | B11: =B7+B8-B9-B10 -> 19900 | C11: =C7+C8-C9-C10 -> 17122.222
A12: Shares (mm) | B12: 300 | C12: =B12 -> 300
A13: NAV / SHARE ($) | B13: =IFERROR(B11/B12,0) -> 66.333333 | C13: =IFERROR(C11/C12,0) -> 57.074074
A15: AFFO-YIELD CROSS-CHECK
A16: AFFO / share ($) | B16: 4 | C16: =B16 -> 4
A17: Target AFFO yield | B17: 0.06 | C17: 0.065
A18: Implied value / share ($) | B18: =IFERROR(B16/B17,0) -> 66.666667 | C18: =IFERROR(C16/C17,0) -> 61.538462

Sheet Phase5_Verdict
A1: PHASE 5 — SENSITIVITY & VERDICT
A3: SENSITIVITY INPUTS (perpetuity basis, $mm)
A4: Next-year FCFF (FCFF1) | B4: =FCFF_DCF!B15 -> 2970
A5: (–) Net debt | B5: =Phase1_Anchor!B16 -> 1200
A6: (–) Minority interest | B6: =Phase1_Anchor!B17 -> 50
A7: (–) Preferred | B7: =Phase1_Anchor!B18 -> 0
A8: (+) Non-op investments | B8: =Phase1_Anchor!B19 -> 100
A9: Diluted shares (mm) | B9: =Phase1_Anchor!B7 -> 520
A10: Base WACC | B10: =WACC_Build!B22 -> 0.089267778
A12: FAIR VALUE / SHARE — Gordon-perpetuity check (off FCFF1; complements 10-yr fade)
A13: WACC \ g | B13: 0 | C13: 0.01 | D13: 0.02 | E13: 0.03
A14: =$B$10+(-0.01) -> 0.079267778 | B14: =IFERROR(IF($A14>0,(($B$4/($A14-0))-$B$5-$B$6-$B$7+$B$8)/$B$9,"n/a"),"n/a") -> 69.842184 | C14: =IFERROR(IF($A14>0.01,(($B$4/($A14-0.01))-$B$5-$B$6-$B$7+$B$8)/$B$9,"n/a"),"n/a") -> 80.244383 | D14: =IFERROR(IF($A14>0.02,(($B$4/($A14-0.02))-$B$5-$B$6-$B$7+$B$8)/$B$9,"n/a"),"n/a") -> 94.15682 | E14: =IFERROR(IF($A14>0.03,(($B$4/($A14-0.03))-$B$5-$B$6-$B$7+$B$8)/$B$9,"n/a"),"n/a") -> 113.71694
A15: =$B$10+(-0.005) -> 0.084267778 | B15: =IFERROR(IF($A15>0,(($B$4/($A15-0))-$B$5-$B$6-$B$7+$B$8)/$B$9,"n/a"),"n/a") -> 65.566901 | C15: =IFERROR(IF($A15>0.01,(($B$4/($A15-0.01))-$B$5-$B$6-$B$7+$B$8)/$B$9,"n/a"),"n/a") -> 74.693125 | D15: =IFERROR(IF($A15>0.02,(($B$4/($A15-0.02))-$B$5-$B$6-$B$7+$B$8)/$B$9,"n/a"),"n/a") -> 86.659411 | E15: =IFERROR(IF($A15>0.03,(($B$4/($A15-0.03))-$B$5-$B$6-$B$7+$B$8)/$B$9,"n/a"),"n/a") -> 103.03579
A16: =$B$10 -> 0.089267778 | B16: =IFERROR(IF($A16>0,(($B$4/($A16-0))-$B$5-$B$6-$B$7+$B$8)/$B$9,"n/a"),"n/a") -> 61.770546 | C16: =IFERROR(IF($A16>0.01,(($B$4/($A16-0.01))-$B$5-$B$6-$B$7+$B$8)/$B$9,"n/a"),"n/a") -> 69.842184 | D16: =IFERROR(IF($A16>0.02,(($B$4/($A16-0.02))-$B$5-$B$6-$B$7+$B$8)/$B$9,"n/a"),"n/a") -> 80.244383 | E16: =IFERROR(IF($A16>0.03,(($B$4/($A16-0.03))-$B$5-$B$6-$B$7+$B$8)/$B$9,"n/a"),"n/a") -> 94.15682
A17: =$B$10+(0.005) -> 0.094267778 | B17: =IFERROR(IF($A17>0,(($B$4/($A17-0))-$B$5-$B$6-$B$7+$B$8)/$B$9,"n/a"),"n/a") -> 58.376911 | C17: =IFERROR(IF($A17>0.01,(($B$4/($A17-0.01))-$B$5-$B$6-$B$7+$B$8)/$B$9,"n/a"),"n/a") -> 65.566901 | D17: =IFERROR(IF($A17>0.02,(($B$4/($A17-0.02))-$B$5-$B$6-$B$7+$B$8)/$B$9,"n/a"),"n/a") -> 74.693125 | E17: =IFERROR(IF($A17>0.03,(($B$4/($A17-0.03))-$B$5-$B$6-$B$7+$B$8)/$B$9,"n/a"),"n/a") -> 86.659411
A18: =$B$10+(0.01) -> 0.099267778 | B18: =IFERROR(IF($A18>0,(($B$4/($A18-0))-$B$5-$B$6-$B$7+$B$8)/$B$9,"n/a"),"n/a") -> 55.325143 | C18: =IFERROR(IF($A18>0.01,(($B$4/($A18-0.01))-$B$5-$B$6-$B$7+$B$8)/$B$9,"n/a"),"n/a") -> 61.770546 | D18: =IFERROR(IF($A18>0.02,(($B$4/($A18-0.02))-$B$5-$B$6-$B$7+$B$8)/$B$9,"n/a"),"n/a") -> 69.842184 | E18: =IFERROR(IF($A18>0.03,(($B$4/($A18-0.03))-$B$5-$B$6-$B$7+$B$8)/$B$9,"n/a"),"n/a") -> 80.244383
A19: Note: simple-perpetuity cross-check off FCFF1; NOT the 2-stage fade DCF (fade result = FCFF_DCF!C33).
A20: STRESS TEST (primary sector shock)
A21: Primary risk channel | B21: Standard: revenue/FCFF shock
A22: Shock to FCFF1 | B22: -0.05
A23: Base FV/sh (Track B) | B23: =FCFF_DCF!C33 -> 103.88947
A24: Stressed FV/sh (perpetuity) | B24: =IFERROR((FCFF_DCF!C24*(1+B22)-$B$5-$B$6-$B$7+$B$8)/$B$9,0) -> 98.584424
A25: Impact | B25: =IFERROR(B24/B23-1,0) -> -0.051064371
A27: FINAL VERDICT
A28: Fair Value — Track A | B28: =FCFF_DCF!B33 -> 63.629714
A29: Fair Value — Track B | B29: =FCFF_DCF!C33 -> 103.88947
A30: Fair Value — average | B30: =AVERAGE(B28:B29) -> 83.759594
A31: Current price P0 | B31: =Phase1_Anchor!B5 -> 100
A32: Margin of Safety | B32: =IFERROR((B30-B31)/B31,0) -> -0.16240406
A33: Institutional rating | B33: Hold
A34: Grounded in terminal risk:
A35: [One-sentence rating tied to the Phase-2 terminal risk + thesis restatement.]
A38: REVENUE-GROWTH SENSITIVITY (Track B, live - ties to FCFF_DCF!C33)
A39: Live base FCFF yr0 ($mm) | B39: =FCFF_DCF!C5 -> 2700
A40: Live terminal g (yr10+) | B40: =FCFF_DCF!C6 -> 0.02
A41: Live WACC | B41: =FCFF_DCF!C7 -> 0.089267778
A42: Stage-1 growth g0 scenario -> | B42: 0.06 | C42: 0.08 | D42: 0.1 | E42: 0.12 | F42: 0.14
A43: Period / DF | H43: DF
A44: 1 | B44: =$B$39*(1+(B$42+($B$40-B$42)*($A44-1)/9)) -> 2862 | C44: =$B$39*(1+(C$42+($B$40-C$42)*($A44-1)/9)) -> 2916 | D44: =$B$39*(1+(D$42+($B$40-D$42)*($A44-1)/9)) -> 2970 | E44: =$B$39*(1+(E$42+($B$40-E$42)*($A44-1)/9)) -> 3024 | F44: =$B$39*(1+(F$42+($B$40-F$42)*($A44-1)/9)) -> 3078 | H44: =1/(1+$B$41)^$A44 -> 0.9180479
A45: 2 | B45: =B44*(1+(B$42+($B$40-B$42)*($A45-1)/9)) -> 3021 | C45: =C44*(1+(C$42+($B$40-C$42)*($A45-1)/9)) -> 3129.84 | D45: =D44*(1+(D$42+($B$40-D$42)*($A45-1)/9)) -> 3240.6 | E45: =E44*(1+(E$42+($B$40-E$42)*($A45-1)/9)) -> 3353.28 | F45: =F44*(1+(F$42+($B$40-F$42)*($A45-1)/9)) -> 3467.88 | H45: =1/(1+$B$41)^$A45 -> 0.84281195
...
